Workbook

Sheet Cover
A2: Smart Financial Recovery Platform — Financial Model
B4: Anchored by the Smart EMI Consolidation Loan (Module 2)
B5: Companion model to the Financially Fitt Pilot Proposal — FINAL version (supersedes v4.1; ask now Phase 0–2, gated).
B6: Prepared by: Nidhi | Deputy Manager, FP&A — August 2026
B7: This model has two layers. The "Phase 0–2 Ask" sheet is the current investment request (₹2–3 cr, Section 7 of the proposal). Every other sheet — Acquisition Funnel through Sensitivity — models the Year-3 platform-scale destination IF the pilot clears its six gates (Section 5). Treat those as illustrative upside, not today’s ask.
B9: Sheet Guide
B10: Sheet | C10: What it contains
B11: Assumptions | C11: All editable inputs: funnel conversion rates, unit economics, risk ranges, growth. Yellow cells are the ones to change.
B12: Acquisition Funnel | C12: Section 11 funnel — existing base through to active consolidated customers, and the resulting Year 1 disbursement base.
B13: Unit Economics | C13: Section 14 per-loan economics for the illustrative Module 2 anchor loan.
B14: 3-Year P&L | C14: Section 21 P&L structure, Years 1–3, built from the Funnel and Unit Economics sheets.
B15: Scenario Analysis | C15: Section 17 Best / Base / Worst case sensitivity on approval rate and credit loss.
B16: Capital Allocation | C16: Section 27 comparison of this platform against alternative uses of the same incremental capital.
B17: CEO Dashboard | C17: Headline metrics (deck Slide 2 / proposal Section 8): baseline vs. Year-3 target.
B18: Capital & Returns | C18: IRR, NPV, payback period, and regulatory capital / ROIC — the board-level capital case (Section 29).
B19: Sensitivity | C19: One-way tornado sensitivity of Year-3 PBT to approval rate, credit loss, yield, cost of funds, and opex.
B20: Executive KPI Dashboard | C20: AUM, NII, credit cost, ROE, CLV, CAC, approval rate, delinquency, collections efficiency, cross-sell, NPA, Stage 2→3 migration.
B21: Data Validation Tracker | C21: Checklist of every illustrative assumption, its owner, and target validation date — the Board's ‘what's still illustrative?’ answer.
... B26: Phase 0–2 Ask | C26: Section 7 — the current investment request: ₹2–3 cr for Phase 0–2 (validation + manual pilot), before any AI/platform-module spend.
B27: Color key: blue text on cream fill = input you can change · black text = formula · green text = link from another sheet. All figures marked ‘illustrative’ in the source document remain illustrative here — replace the yellow-highlighted assumption cells with validated data before using this model for an investment decision (see the Data Validation Tracker sheet in this workbook).
B29: Note on 'Section N' references in this workbook: most refer to the presentation's own slide-section numbering (the SECTION headers on each deck slide), which matches this model's own sheet titles — not to the numbered headings in the FINAL proposal document, which runs only to Section 13.2 after the Phase 0–2 pivot. Where a reference explicitly cites 'the proposal,' it has been corrected to the actual matching proposal section, or retargeted to the deck slide / Excel sheet that genuinely contains that detail.

Sheet Phase 0-2 Ask
A1: Phase 0–2 Ask — The Current Investment Request (Section 7 of the Proposal)
B3: This is the entire current ask: ₹2–3 crore for Phase 0–2 only — not the ₹5.7–9.7 crore previously scoped for building the AI modules, and not a platform-scale commitment. Every rupee beyond this requires the six gates in Section 5 to be cleared first. AI/platform-module costs (Modules 1, 3–6) are intentionally excluded — they are Phase 5–6 decisions.
B6: Item | C6: Phase | D6: Low (₹ lakh) | E6: High (₹ lakh) | F6: Note
B7: Customer & stakeholder interviews, historical data analysis | C7: Phase 0 | D7: 15 | E7: 25
B8: Manual MVP build (web portal, dashboard, approval workflow — no ML) | C8: Phase 1 | D8: 60 | E8: 90
B9: RM / operations capacity for ~500-customer pilot | C9: Phase 2 | D9: 50 | E9: 80 | F9: Run-rate, pilot period
B10: Settlement / payment-rail testing across 3+ external lenders | C10: Phase 1–2 | D10: 20 | E10: 35
B11: Legal / compliance / RBI-guidance review | C11: Phase 0–1 | D11: 15 | E11: 25
B12: Contingency | C12: — | D12: 20 | E12: 30
B13: Total, Phase 0–2 (₹ lakh) | D13: =SUM(D7:D12) -> 180 | E13: =SUM(E7:E12) -> 285
B14: Total, Phase 0–2 (₹ crore) | D14: =D13/100 -> 1.8 | E14: =E13/100 -> 2.85
B16: Every other sheet in this workbook (Acquisition Funnel through Sensitivity, Capital & Returns, Executive KPI Dashboard) models the Year-3 platform-scale destination — illustrative upside IF this pilot clears its six gates (Customer, Risk, Operations, Financial, Governance, Scale — Section 5 of the proposal), not the current ask. The Year-3 CEO Dashboard targets and the ₹8.3 cr / IRR / NPV figures elsewhere in this workbook describe that destination case, not what is being requested today.

Sheet Assumptions
B1: Assumptions — edit yellow cells only
A3: 1. Acquisition Funnel (Section 11)
B4: Assumption | C4: Value
B5: Existing customer base | C5: 1000000
B6: % holding multiple loans | C6: 0.2
B7: % of multi-loan flagged high-stress by Module 1 | C7: 0.3
B8: % of flagged that are policy-eligible | C8: 0.42
B9: % of eligible that apply / accept offer | C9: 0.4
B10: % of applicants approved | C10: 0.6
B11: % of approved that go active | C11: 0.83
A13: 2. Unit Economics (Section 14, Module 2 Anchor Loan)
B14: Assumption | C14: Value
B15: Average sanctioned amount per loan (₹) | C15: 120000
B16: Average tenor (months) | C16: 30
B17: Yield (% p.a.) | C17: 0.18
B18: Cost of funds (% p.a.) | C18: 0.1
B19: Processing fee (% of sanctioned amount) | C19: 0.02
B20: Operating cost per loan (₹) | C20: 1500
A22: 3. Risk Framework — Base Case (Section 13)
B23: Assumption | C23: Value
B24: Net credit loss rate — base case (% of avg book) | C24: 0.03
B25: Net credit loss rate — conservative/worst case | C25: 0.06
B26: Net credit loss rate — best case | C26: 0.015
B27: Approval rate — base case | C27: 0.25
B28: Approval rate — worst case | C28: 0.1
B29: Approval rate — best case | C29: 0.35
A31: 4. Growth, Book Build-Up & Cost (Section 21)
B32: Assumption | C32: Value
B33: Disbursement growth, Year 2 vs Year 1 | C33: 1.5
B34: Disbursement growth, Year 3 vs Year 2 | C34: 1.33
B35: Annual book run-off rate (repayment/prepayment) | C35: 0.45
B36: Fixed platform operating cost — Year 1 (₹ cr) | C36: 2
B37: Fixed platform operating cost — Year 2 (₹ cr) | C37: 2.5
B38: Fixed platform operating cost — Year 3 (₹ cr) | C38: 3
B39: Tax rate | C39: 0.25
A42: 5. Capital, Cost of Capital & Returns
B43: Assumption | C43: Value
B44: Platform build cost, Year 0 (₹ cr) | C44: ='Implementation Budget'!C12 -> 8.3
B45: Cost of equity / hurdle rate (Ke) | C45: 0.15
B46: Capital adequacy ratio required (CRAR) | C46: 0.15
...

Sheet Acquisition Funnel
B1: Acquisition Funnel (Section 11)
B3: Funnel Step | C3: Customers | D3: Conversion | E3: Driver (from Assumptions)
B4: Existing customer base | C4: =Assumptions!$C$5 -> 1000000
B5: Holding multiple loans | C5: =C4*Assumptions!$C$6 -> 200000 | D5: =C5/C4 -> 0.2 | E5: % holding multiple loans
B6: Flagged high-stress by Module 1 | C6: =C5*Assumptions!$C$7 -> 60000 | D6: =C6/C5 -> 0.3 | E6: % flagged high-stress
B7: Policy-eligible | C7: =C6*Assumptions!$C$8 -> 25200 | D7: =C7/C6 -> 0.42 | E7: % policy-eligible
B8: Apply / accept offer | C8: =C7*Assumptions!$C$9 -> 10080 | D8: =C8/C7 -> 0.4 | E8: % apply / accept
B9: Approved | C9: =C8*Assumptions!$C$10 -> 6048 | D9: =C9/C8 -> 0.6 | E9: % approved
B10: Active consolidated customers | C10: =C9*Assumptions!$C$11 -> 5019.84 | D10: =C10/C9 -> 0.83 | E10: % active
B13: Conversion rates are illustrative pilot targets shown on deck Slide 8 — this level of funnel detail is not carried as a numbered section in the FINAL proposal document. The Pilot Design sheet is designed to measure and replace each rate with an observed value.
B15: Year 1 Disbursement Base
B16: Active consolidated customers (Year 1) | C16: =C10 -> 5019.84
B17: Average ticket size (₹) | C17: =Assumptions!$C$15 -> 120000
B18: Year 1 disbursements (₹ cr) | C18: =C16*C17/10000000 -> 60.23808

Sheet Unit Economics
B1: Unit Economics — Module 2 Anchor Loan (Section 14)
B3: Component | C3: Value | D3: Formula
B4: Sanctioned amount (₹) | C4: =Assumptions!$C$15 -> 120000 | D4: Link: Assumptions
B5: Average outstanding book (approx., ₹) | C5: =C4*0.5 -> 60000 | D5: Formula: Sanctioned × 50% (average over amortising tenor)
B6: Gross interest margin (₹, on average book) | C6: =C5*(Assumptions!$C$17-Assumptions!$C$18) -> 4800 | D6: Formula: Avg book × (Yield − Cost of funds)
B7: Fee income — upfront (₹) | C7: =C4*Assumptions!$C$19 -> 2400 | D7: Formula: Sanctioned amount × processing fee %
B8: Credit cost (₹) | C8: =C5*Assumptions!$C$24 -> 1800 | D8: Formula: Avg book × base-case net credit loss %
B9: Operating cost (₹) | C9: =Assumptions!$C$20 -> 1500 | D9: Link: Assumptions
B11: Net contribution per loan (₹) | C11: =C6+C7-C8-C9 -> 3900
B13: Matches the illustrative per-loan structure shown on deck Slide 11/18 (₹1,20,000 sanctioned, 30-month tenor, 18% yield, 10% cost of funds, 2% fee, 3% credit cost, ₹1,500 opex). Average book is approximated at 50% of sanctioned amount for a straight-line amortising loan — refine against the company's actual amortisation schedule before use.

Sheet 3-Year P&L
B1: 3-Year P&L Projection — Module 2 Anchor Loan (Section 21)
B3: Line Item (₹ cr unless noted) | C3: Year 1 | D3: Year 2 | E3: Year 3 | F3: Formula (Year 1 shown)
B4: Disbursements | C4: ='Acquisition Funnel'!$C$18 -> 60.23808 | D4: =C4*(1+Assumptions!$C$33) -> 150.5952 | E4: =D4*(1+Assumptions!$C$34) -> 350.88682 | F4: Year 1 link: Acquisition Funnel; Yr2/Yr3 = prior year × (1 + growth rate)
B5: Average loan book | C5: =0.5*C4 -> 30.11904 | D5: =C5*(1-Assumptions!$C$35)+0.5*D4 -> 91.863072 | E5: =D5*(1-Assumptions!$C$35)+0.5*E4 -> 225.9681 | F5: Prior book × (1 − run-off) + 50% of current-year disbursements
B7: Interest income | C7: =C5*Assumptions!$C$17 -> 5.4214272 | D7: =D5*Assumptions!$C$17 -> 16.535353 | E7: =E5*Assumptions!$C$17 -> 40.674258 | F7: Formula: Average book × yield %
B8: Interest expense | C8: =C5*Assumptions!$C$18 -> 3.011904 | D8: =D5*Assumptions!$C$18 -> 9.1863072 | E8: =E5*Assumptions!$C$18 -> 22.59681 | F8: Formula: Average book × cost of funds %
B9: Net interest income (NII) | C9: =C7-C8 -> 2.4095232 | D9: =D7-D8 -> 7.3490458 | E9: =E7-E8 -> 18.077448 | F9: Formula: Interest income − Interest expense
B10: Fee income | C10: =C4*Assumptions!$C$19 -> 1.2047616 | D10: =D4*Assumptions!$C$19 -> 3.011904 | E10: =E4*Assumptions!$C$19 -> 7.0177363 | F10: Formula: Disbursements × fee %
B11: Total operating income | C11: =C9+C10 -> 3.6142848 | D11: =D9+D10 -> 10.36095 | E11: =E9+E10 -> 25.095184 | F11: Formula: NII + Fee income
B13: Variable opex (active loans × opex/loan) | C13: ='Acquisition Funnel'!$C$16*Assumptions!$C$20/10000000 -> 0.752976 | D13: =C13*(1+Assumptions!$C$33) -> 1.88244 | E13: =D13*(1+Assumptions!$C$34) -> 4.3860852 | F13: Formula: Active loans × opex per loan, scaled with growth in Yr2/Yr3
B14: Fixed platform operating cost | C14: =Assumptions!$C$36 -> 2 | D14: =Assumptions!$C$37 -> 2.5 | E14: =Assumptions!$C$38 -> 3 | F14: Link: Assumptions
B15: Total operating expense | C15: =C13+C14 -> 2.752976 | D15: =D13+D14 -> 4.38244 | E15: =E13+E14 -> 7.3860852 | F15: Formula: Variable opex + Fixed platform cost
B16: Credit cost | C16: =C5*Assumptions!$C$24 -> 0.9035712 | D16: =D5*Assumptions!$C$24 -> 2.7558922 | E16: =E5*Assumptions!$C$24 -> 6.7790429 | F16: Formula: Average book × base-case net credit loss %
B18: PBT | C18: =C11-C15-C16 -> -0.0422624 | D18: =D11-D15-D16 -> 3.2226176 | E18: =E11-E15-E16 -> 10.930056 | F18: Formula: Operating income − Opex − Credit cost
B19: Tax | C19: =MAX(0,C18)*Assumptions!$C$39 -> 0 | D19: =MAX(0,D18)*Assumptions!$C$39 -> 0.8056544 | E19: =MAX(0,E18)*Assumptions!$C$39 -> 2.732514 | F19: Formula: MAX(0, PBT) × tax rate (no tax benefit assumed on a loss year)
B20: PAT | C20: =C18-C19 -> -0.0422624 | D20: =D18-D19 -> 2.4169632 | E20: =E18-E19 -> 8.197542 | F20: Formula: PBT − Tax
B23: Structure follows the 3-Year Financial Projection shown on deck Slide 19. Book build-up and growth-rate assumptions are set in the Assumptions sheet so the projection can be recalculated as pilot data (Section 19) replaces the illustrative funnel and risk inputs.

Sheet Scenario Analysis
B1: Scenario Analysis — Year 3, Module 2 Book (Section 17)
B3: Metric | C3: Worst Case | D3: Base Case | E3: Best Case | F3: Driver
B4: Approval rate | C4: =Assumptions!$C$28 -> 0.1 | D4: =Assumptions!$C$27 -> 0.25 | E4: =Assumptions!$C$29 -> 0.35 | F4: Link: Assumptions risk framework
B5: Net credit loss rate | C5: =Assumptions!$C$25 -> 0.06 | D5: =Assumptions!$C$24 -> 0.03 | E5: =Assumptions!$C$26 -> 0.015 | F5: Link: Assumptions risk framework
B6: Average book (₹ cr) | C6: ='3-Year P&L'!$E$5*C4/Assumptions!$C$27 -> 90.387239 | D6: ='3-Year P&L'!$E$5 -> 225.9681 | E6: ='3-Year P&L'!$E$5*E4/Assumptions!$C$27 -> 316.35534 | F6: Base case links to 3-Year P&L Year 3; Worst/Best scaled by relative approval rate
B7: Credit cost (₹ cr) | C7: =C6*C5 -> 5.4232343 | D7: =D6*D5 -> 6.7790429 | E7: =E6*E5 -> 4.74533 | F7: Formula: Average book × net credit loss rate
B8: Operating income (₹ cr, illustrative, scaled with book) | C8: ='3-Year P&L'!$E$11*C6/'3-Year P&L'!$E$5 -> 10.038074 | D8: ='3-Year P&L'!$E$11 -> 25.095184 | E8: ='3-Year P&L'!$E$11*E6/'3-Year P&L'!$E$5 -> 35.133258 | F8: Scales Year-3 base-case operating income with the scenario book size
B9: Operating expense (₹ cr, held flat) | C9: ='3-Year P&L'!$E$15 -> 7.3860852 | D9: ='3-Year P&L'!$E$15 -> 7.3860852 | E9: ='3-Year P&L'!$E$15 -> 7.3860852 | F9: Fixed + variable opex held at base-case Year 3 level across scenarios
B10: PBT (₹ cr) | C10: =C8-C9-C7 -> -2.7712459 | D10: =D8-D9-D7 -> 10.930056 | E10: =E8-E9-E7 -> 23.001843 | F10: Formula: Operating income − Opex − Credit cost
B13: Reproduces the structure of Section 17.1. The worst/best case average book scales the base-case Year-3 book (from the 3-Year P&L sheet) by the relative approval rate, consistent with the proposal's own directional framing — replace with a full scenario re-run of the funnel and P&L sheets for a rigorous stress test.

Sheet Pilot Design
B1: Pilot Design & A/B Test — Sample Size, Metrics, Go/No-Go (Section 19)
A3: 1. Pilot Structure
B4: Regions | C4: 1–2, sufficient flagged-customer volume for significance within 6 months
B5: Duration | C5: 6–9 months, go/no-go review at month 6
B6: Population | C6: Existing customers flagged by Module 1's rules-based version
B7: Treatment group | C7: Receives proactive, pre-qualified consolidation offer via app/RM
B8: Control group | C8: Standard marketing / no proactive offer, tracked on the same metrics
A10: 2. Sample Size Calculation — Two-Proportion Test
B11: Input | C11: Value | D11: Note
B12: Baseline 90-day delinquency (control), p1 | C12: =Assumptions!C24 -> 0.03 | D12: Linked: Assumptions, base-case net credit loss rate used as delinquency proxy
B13: Expected absolute reduction (treatment), pp | C13: 0.015 | D13: Illustrative — the smallest effect worth detecting; tighten once pilot data exists
B14: Significance level, alpha (two-sided) | C14: 0.05 | D14: Standard 5% significance
B15: Statistical power, 1-beta | C15: 0.8 | D15: Standard 80% power
B17: p2 (treatment delinquency) | C17: =C12-C13 -> 0.015 | D17: Formula: p1 − expected reduction
B18: Z (alpha/2) | C18: =NORMSINV(1-C14/2) -> 1.959964
B19: Z (power) | C19: =NORMSINV(C15) -> 0.84162123
B21: Required sample size per arm (n) | C21: =ROUNDUP(((C18+C19)^2*(C12*(1-C12)+C17*(1-C17)))/(C12-C17)^2,0) -> 1531 | D21: Two-proportion z-test, standard formula — recompute once real baseline delinquency (from pilot data) replaces the linked assumption
B22: Total pilot population needed (both arms) | C22: =C21*2 -> 3062 | D22: Compare against 'Policy-eligible' pool size on the Acquisition Funnel sheet to confirm the pilot region(s) can supply this volume
A24: 3. Success Metrics
B25: Metric | C25: Type | D25: Threshold
B26: 90-day and 180-day delinquency, treatment vs. control | C26: Primary | D26: Treatment at or below base-case net credit loss rate (Assumptions)
B27: Offer acceptance rate | C27: Secondary | D27: ≥ 70% of the CEO Dashboard target funnel rate
B28: Retention at 12 months | C28: Secondary | D28: ≥ 70% of the CEO Dashboard Yr-3 retention target
B29: Cross-sell attach rate at 6 months | C29: Secondary | D29: Directionally positive vs. non-pilot base
B30: Complaint rate / regulatory escalations | C30: Guardrail | D30: No material increase vs. book average
B31: Model bias check across demographic segments | C31: Guardrail | D31: No statistically significant disparity in approval/pricing
A33: 4. Go / No-Go Decision Rule
B34: Decision | C34: Condition | D34: Action
B35: GO | C35: Treatment delinquency ≤ base case, acceptance & retention ≥ 70% of target | D35: Proceed to Phase 2 scale-up
B36: RECALIBRATE | C36: Directionally positive but below threshold | D36: Adjust eligibility rules or offer design, re-test
B37: NO-GO | C37: Treatment delinquency ≥ conservative case, or guardrail breach | D37: Stop; escalate to Risk & Board
B39: Sample-size math is a standard two-proportion power calculation for board-discussion purposes. Statistics/Risk should confirm the minimum-detectable-effect assumption (currently 1.5pp) and re-run before the pilot is finalised.

Sheet Capital Allocation
B1: Capital Allocation Comparison (Section 27)
B3: Investment Option | C3: Expected ROE | D3: Risk | E3: Capital Intensity | F3: Strategic Value
B4: New Personal Loan Product (new customers) | C4: Medium | D4: Medium | E4: High | F4: Medium
B5: Credit Card Expansion | C5: High | D5: High | E5: Medium | F5: Medium
B6: SME Lending | C6: Medium | D6: High | E6: High | F6: Medium
B7: Smart Financial Recovery Platform (this proposal) | C7: Medium–High | D7: Lower | E7: Low | F7: High
B10: This platform is not rated highest on expected ROE alone — credit card expansion rates higher on that single dimension. The case rests on deploying capital against existing, behaviourally-known customers with a built-in early-warning system (deck Slide 3, Value Creation Chain), which is why risk and capital intensity are rated lower than the new-customer alternatives. See deck Slide 22 (Capital Allocation) and proposal Section 8 for the full argument.

Sheet CEO Dashboard
B1: CEO Dashboard — Headline Metrics (deck Slide 2 / proposal Section 8)
B3: Metric | C3: Current (Baseline) | D3: After Platform (Yr 3 Target) | E3: Source
B4: Customer retention | C4: 0.72 | D4: 0.86 | E4: Section 8
B5: NPA / GNPA | C5: 0.034 | D5: 0.028 | E5: Section 8
B6: Customer lifetime value (CLV, ₹) | C6: 38000 | D6: 54000 | E6: Section 8
B7: Cross-sell rate | C7: 0.18 | D7: 0.34 | E7: Section 8
B8: Return on equity (ROE) | C8: 0.175 | D8: 0.186 | E8: Section 8
B9: Incremental annual PBT, Year 3 (₹ cr) — this model | C9: ='3-Year P&L'!$E$18 -> 10.930056 | E9: Live link — 3-Year P&L, Year 3
B10: Illustrative range quoted in proposal Section 8 (₹ cr) | C10: 18–22
B12: Baseline and Year-3 target cells are inputs (blue) so this dashboard can be refreshed once the company's actual retention, NPA, CLV and ROE baselines replace the illustrative figures (Section 24.2, item 1). The PBT line is a live formula link to the 3-Year P&L sheet, so it moves automatically as assumptions are updated. These Year-3 figures are the platform-scale destination if the Phase 0–2 pilot clears its gates (Section 5) — they are not the basis for the current funding ask (see 'Phase 0–2 Ask' sheet).

Sheet Capital & Returns
B1: Capital, IRR, NPV & Payback — Module 2 Anchor Loan
C3: Year 0 | D3: Year 1 | E3: Year 2 | F3: Year 3 | G3: Formula
B4: Cash flow (₹ cr) | C4: =-Assumptions!$C$44 -> -8.3 | D4: ='3-Year P&L'!$C$20 -> -0.0422624 | E4: ='3-Year P&L'!$D$20 -> 2.4169632 | F4: ='3-Year P&L'!$E$20+F5 -> 94.271733 | G4: Year 0 = −build cost; Yr1–3 = PAT (link: 3-Year P&L); Yr3 also carries terminal value below
B5: Terminal value, end of Year 3 (₹ cr) | F5: ='3-Year P&L'!$E$20*(1+Assumptions!$C$48)/(Assumptions!$C$45-Assumptions!$C$48) -> 86.074191 | G5: Gordon growth perpetuity on Year-3 PAT: PAT×(1+g)/(Ke−g)
B6: Cash flow, excl. terminal value (₹ cr) | C6: =-Assumptions!$C$44 -> -8.3 | D6: ='3-Year P&L'!$C$20 -> -0.0422624 | E6: ='3-Year P&L'!$D$20 -> 2.4169632 | F6: ='3-Year P&L'!$E$20 -> 8.197542 | G6: Same as above but Year 3 = PAT only, no perpetuity — used for the conservative IRR/NPV below
B8: IRR (Years 0–3, incl. terminal value) | C8: =IRR(C4:F4,0.3) -> 1.2893013 | G8: Formula: IRR() on the Year 0–3 cash flow row above
B9: NPV @ cost of equity (₹ cr) | C9: =NPV(Assumptions!$C$45,D4:F4)+C4 -> 55.476016 | G9: Formula: NPV(Ke, Yr1:Yr3) + Yr0 outflow (undiscounted, t=0)
B10: Payback period (years) | C10: =IF(D4+C4>0,1+(-C4)/D4,IF(D4+E4+C4>0,2+(-C4-D4)/E4,3+(-C4-D4-E4)/'3-Year P&L'!$E$20)) -> 3.7228141 | G10: Simple (undiscounted) payback — first year cumulative PAT exceeds build cost
B11: — IRR, excluding terminal value (conservative) | C11: =IRR(C6:F6,0.1) -> 0.091212057 | G11: Formula: IRR() on Years 0–2 plus Year-3 PAT only, no perpetuity
B12: — NPV, excluding terminal value (conservative, ₹ cr) | C12: =NPV(Assumptions!$C$45,D6:F6)+C6 -> -1.1191616 | G12: Formula: NPV(Ke, Yr1, Yr2, Yr3 PAT only) + Yr0 outflow, no perpetuity
B13: The headline IRR/NPV above include a Year-3 terminal value using a Gordon growth perpetuity (PAT growing at 5% forever, discounted at 15%) — this is standard DCF practice but the multiple it implies (~10.5x Year-3 PAT) is aggressive for a still-nascent book. The ‘excluding terminal value’ rows above are the conservative read: value from the three explicit years only. Treasury/FP&A should present both to the Board, not the headline number alone.
B15: Capital Required & Return on Regulatory Capital
C16: Year 1 | D16: Year 2 | E16: Year 3 | F16: Formula
B17: Average loan book (₹ cr) | C17: ='3-Year P&L'!$C$5 -> 30.11904 | D17: ='3-Year P&L'!$D$5 -> 91.863072 | E17: ='3-Year P&L'!$E$5 -> 225.9681 | F17: Link: 3-Year P&L
B18: Regulatory capital required (₹ cr) | C18: =C17*Assumptions!$C$46 -> 4.517856 | D18: =D17*Assumptions!$C$46 -> 13.779461 | E18: =E17*Assumptions!$C$46 -> 33.895215 | F18: Formula: Average book × CRAR requirement
B19: % of current CET1 base absorbed | C19: =C18/Assumptions!$C$47 -> 0.009035712 | D19: =D18/Assumptions!$C$47 -> 0.027558922 | E19: =E18/Assumptions!$C$47 -> 0.067790429 | F19: Formula: Capital required / CET1 base — incremental capital consumption
B20: Return on regulatory capital (ROIC) | C20: ='3-Year P&L'!$C$20/C18 -> -0.0093545257 | D20: ='3-Year P&L'!$D$20/D18 -> 0.17540332 | E20: ='3-Year P&L'!$E$20/E18 -> 0.24184954 | F20: Formula: PAT / Capital required
B21: Economic Profit / EVA (₹ cr) | C21: ='3-Year P&L'!$C$20-C18*Assumptions!$C$45 -> -0.7199408 | D21: ='3-Year P&L'!$D$20-D18*Assumptions!$C$45 -> 0.35004408 | E21: ='3-Year P&L'!$E$20-E18*Assumptions!$C$45 -> 3.1132598 | F21: Formula: PAT − (Regulatory capital required × Cost of equity) — Economic Value Added on regulatory capital
B23: This is a board-discussion-grade capital view, not a treasury ALM/liquidity model. It excludes funding-mix impact, RWA density variation by risk-weight bucket, and Basel/RBI-specific NBFC capital treatment nuances — Finance/Treasury should re-run this with the actual CRAR methodology before it is used in a capital-adequacy submission (see the Data Validation Tracker sheet; deck Slide 27, Regulatory & Compliance). This entire sheet is Year-3 destination-case economics, contingent on Phase 0–2 clearing its gates — the current ask carries no IRR/NPV of its own (see 'Phase 0–2 Ask' sheet, Section 7).

Sheet Sensitivity
B1: Sensitivity — Year 3 PBT Drivers
B3: Driver | C3: Downside | D3: Base | E3: Upside | F3: Swing (₹ cr) | G3: Method
B4: Approval rate (± vs. base) | C4: ='3-Year P&L'!$E$18-'3-Year P&L'!$E$5*(1-Assumptions!$C$28/Assumptions!$C$27)*(Assumptions!$C$17-Assumptions!$C$18+Assumptions!$C$24) -> -3.9838384 | D4: ='3-Year P&L'!$E$18 -> 10.930056 | E4: ='3-Year P&L'!$E$18+'3-Year P&L'!$E$5*(Assumptions!$C$29/Assumptions!$C$27-1)*(Assumptions!$C$17-Assumptions!$C$18+Assumptions!$C$24) -> 20.872652 | F4: =E4-C4 -> 24.856491 | G4: Book scaled by relative approval rate; margin+credit cost rate applied to the delta
B5: Net credit loss rate (± vs. base) | C5: ='3-Year P&L'!$E$18-'3-Year P&L'!$E$5*(Assumptions!$C$25-Assumptions!$C$24) -> 4.1510131 | D5: ='3-Year P&L'!$E$18 -> 10.930056 | E5: ='3-Year P&L'!$E$18+'3-Year P&L'!$E$5*(Assumptions!$C$24-Assumptions!$C$26) -> 14.319577 | F5: =E5-C5 -> 10.168564 | G5: Formula: Base PBT ∓ Average book × change in loss rate
B6: Yield (± 100 bps) | C6: ='3-Year P&L'!$E$18-'3-Year P&L'!$E$5*0.01 -> 8.670375 | D6: ='3-Year P&L'!$E$18 -> 10.930056 | E6: ='3-Year P&L'!$E$18+'3-Year P&L'!$E$5*0.01 -> 13.189737 | F6: =E6-C6 -> 4.519362 | G6: Formula: Base PBT ± Average book × 100 bps
B7: Cost of funds (± 100 bps) | C7: ='3-Year P&L'!$E$18-'3-Year P&L'!$E$5*0.01 -> 8.670375 | D7: ='3-Year P&L'!$E$18 -> 10.930056 | E7: ='3-Year P&L'!$E$18+'3-Year P&L'!$E$5*0.01 -> 13.189737 | F7: =E7-C7 -> 4.519362 | G7: Formula: Base PBT ∓/+ Average book × 100 bps (inverse of yield)
B8: Operating expense (± 10%) | C8: ='3-Year P&L'!$E$18-'3-Year P&L'!$E$15*0.1 -> 10.191447 | D8: ='3-Year P&L'!$E$18 -> 10.930056 | E8: ='3-Year P&L'!$E$18+'3-Year P&L'!$E$15*0.1 -> 11.668665 | F8: =E8-C8 -> 1.477217 | G8: Formula: Base PBT ∓/+ 10% of Year-3 total opex
B10: One-way sensitivities around the Year-3 base-case PBT, held independently (not combined). Use alongside the Scenario Analysis sheet, which combines approval rate and loss rate together for a full worst/best case. Chart below reads as a tornado — longer bars are higher-impact drivers.

Sheet Executive KPI Dashboard
B1: Executive KPI Dashboard — Year 3
B3: KPI | C3: Year 1 | D3: Year 2 | E3: Year 3 | F3: Formula / Source
B4: AUM — average book (₹ cr) | C4: ='3-Year P&L'!C5 -> 30.11904 | D4: ='3-Year P&L'!D5 -> 91.863072 | E4: ='3-Year P&L'!E5 -> 225.9681 | F4: Link: 3-Year P&L
B5: NII (₹ cr) | C5: ='3-Year P&L'!C9 -> 2.4095232 | D5: ='3-Year P&L'!D9 -> 7.3490458 | E5: ='3-Year P&L'!E9 -> 18.077448 | F5: Link: 3-Year P&L
B6: Credit cost (₹ cr) | C6: ='3-Year P&L'!C16 -> 0.9035712 | D6: ='3-Year P&L'!D16 -> 2.7558922 | E6: ='3-Year P&L'!E16 -> 6.7790429 | F6: Link: 3-Year P&L
B7: ROE contribution (PAT / capital required) | C7: ='Capital & Returns'!C20 -> -0.0093545257 | D7: ='Capital & Returns'!D20 -> 0.17540332 | E7: ='Capital & Returns'!E20 -> 0.24184954 | F7: Link: Capital & Returns (ROIC)
B8: Customer lifetime value, CLV (₹) | C8: 38000 | D8: 46000 | E8: 54000 | F8: Link: CEO Dashboard (illustrative baseline → target)
B9: Customer acquisition cost, CAC (₹) | C9: 450 | D9: 400 | E9: 350 | F9: Illustrative — lower over time as own-base channel dominates (deck Slide 14, Go-To-Market Strategy)
B10: Approval rate | C10: =Assumptions!$C$27 -> 0.25 | D10: =Assumptions!$C$27 -> 0.25 | E10: =Assumptions!$C$27 -> 0.25 | F10: Link: Assumptions (base case)
B11: Delinquency / net credit loss rate | C11: =Assumptions!$C$24 -> 0.03 | D11: =Assumptions!$C$24 -> 0.03 | E11: =Assumptions!$C$24 -> 0.03 | F11: Link: Assumptions (base case)
B12: Collections efficiency (illustrative) | C12: 0.92 | D12: 0.94 | E12: 0.96 | F12: Illustrative — improves as Module 4 reduces re-borrowing (deck Slide 10, Module 4 — Financial Wellness)
B13: Cross-sell rate | C13: 0.18 | D13: 0.26 | E13: 0.34 | F13: Link: CEO Dashboard (illustrative baseline → target)
B14: NPA / GNPA (book-level, illustrative) | C14: 0.034 | D14: 0.031 | E14: 0.028 | F14: Link: CEO Dashboard (illustrative baseline → target)
B15: Stage 2 → Stage 3 migration rate (illustrative) | C15: 0.09 | D15: 0.075 | E15: 0.06 | F15: Illustrative — directional only; requires ECL model output to validate
B17: AUM, NII, credit cost and ROE contribution are live formula links and move automatically with the rest of the model. CLV, CAC, collections efficiency, cross-sell, NPA and Stage 2→3 migration are illustrative inputs (Section 24.2) — replace with the actual portfolio-monitoring feed once available so this becomes a live ongoing-performance dashboard, not just a projection.

Sheet Board Scorecard
B1: Board Scorecard — The Five Metrics That Matter
B3: If these five improve, the platform is succeeding. Everything else in this workbook rolls up into one of these.
B5: Metric | C5: Definition | D5: Pilot Target (Yr 1) | E5: Yr 3 Target
B6: 1. Stress Detection Accuracy | C6: % of Module-1-flagged customers who go on to show genuine repayment stress within 90 days (precision of the flagging model) | D6: 0.6 | E6: 0.75
B7: 2. Customer Cure Rate | C7: % of enrolled customers who move from flagged/stressed to current with no missed payment within 6 months of consolidation | D7: 0.65 | E7: 0.8
B8: 3. Re-borrowing Rate | C8: % of consolidated customers who take on new unsecured debt within 6 months of consolidation (lower is better) | D8: 0.2 | E8: 0.12
B9: 4. Net Credit Loss | C9: Net credit loss on the consolidation book as a % of average book (base case, linked live from Assumptions) | D9: =Assumptions!C24 -> 0.03 | E9: =Assumptions!C24 -> 0.03
B10: 5. Risk-Adjusted ROE | C10: Return on regulatory capital (PAT / regulatory capital required) — links live to the Capital & Returns sheet | D10: ='Capital & Returns'!C20 -> -0.0093545257 | E10: ='Capital & Returns'!E20 -> 0.24184954
B12: Metrics 1–3 are new — they don't exist elsewhere in this model because Module 1 hasn't been built yet. They are illustrative placeholders (blue) to be replaced once the pilot's bureau-refresh and repayment data start flowing (see Data Validation Tracker). Metrics 4–5 are live formula links and already move with the rest of the model.

Sheet Data Validation Tracker
B1: Data Validation Tracker — Illustrative → Validated
B3: Assumption Area | C3: Sheet(s) Affected | D3: Owner | E3: Target | F3: Status
B4: Funnel conversion rates (base, flag, eligible, apply, approve, active) | C4: Acquisition Funnel | D4: FP&A + Data Science | E4: Pre-pilot (Month 1–2) | F4: Illustrative
B5: Risk parameters — net credit loss, approval rate ranges | C5: Assumptions, Scenario Analysis | D5: Chief Risk Officer | E5: Pre-pilot (Month 1–2) | F5: Illustrative
B6: Unit economics — yield, cost of funds, fee % | C6: Unit Economics, 3-Year P&L | D6: Treasury / Finance | E6: Pre-pilot (Month 1–2) | F6: Illustrative
B7: Customer baseline — retention, NPA, CLV, ROE | C7: CEO Dashboard, Executive KPI Dashboard | D7: FP&A | E7: Month 1 | F7: Illustrative
B8: Technology build-cost estimates | C8: Implementation Budget | D8: Technology | E8: Month 1–2 (vendor RFP) | F8: Illustrative
B9: Competitive intelligence | C9: n/a — proposal Section 6 | D9: Strategy / Product | E9: Month 2 | F9: Illustrative
B10: Capital adequacy / CRAR methodology | C10: Capital & Returns | D10: Treasury | E10: Pre-capital submission | F10: Illustrative
B11: Cost of equity / hurdle rate | C11: Capital & Returns | D11: Finance / Treasury | E11: Pre-capital submission | F11: Illustrative
B13: Status is an editable input (blue) — update each row to ‘Validated’ as real data replaces the illustrative figure in the referenced sheet(s). This tracker is the single checklist a Board can use to ask ‘what's still illustrative in this model?’ at any point before an investment decision.

Sheet Implementation Budget
B1: Implementation Budget by Function — Year 1
B3: Editable Cost Assumptions
B4: Function | C4: Cost (₹ cr)
B5: Technology (build — Section 30) | C5: 5.5
B6: Operations (settlement rails, collections tooling) | C6: 0.8
B7: Risk (model validation, monitoring) | C7: 0.6
B8: Compliance (legal review, DPIA, regulatory sign-off) | C8: 0.4
B9: Marketing (in-app / own-base comms only, Phase 1) | C9: 0.3
B10: HR (frontline & collections staff training) | C10: 0.3
B11: Collections (outreach system integration & training) | C11: 0.4
B12: Total Year 1 implementation budget | C12: =SUM(C5:C11) -> 8.3
B14: % of total — by function
B15: Function | C15: % of Total
B16: Technology (build — Section 30) | C16: =C5/$C$12 -> 0.6626506
B17: Operations (settlement rails, collections tooling) | C17: =C6/$C$12 -> 0.096385542
B18: Risk (model validation, monitoring) | C18: =C7/$C$12 -> 0.072289157
B19: Compliance (legal review, DPIA, regulatory sign-off) | C19: =C8/$C$12 -> 0.048192771
B20: Marketing (in-app / own-base comms only, Phase 1) | C20: =C9/$C$12 -> 0.036144578
B21: HR (frontline & collections staff training) | C21: =C10/$C$12 -> 0.036144578
B22: Collections (outreach system integration & training) | C22: =C11/$C$12 -> 0.048192771
B24: Technology's ₹5.5 cr sits inside the ₹4–7 cr range estimated by module in Section 30; the remaining functions are illustrative planning allocations, not vendor quotes. This total is the number that should appear on the Board Recommendation page as the Year-1 investment ask — replace all rows with actual functional budget submissions before that ask is finalised.

Sheet Chart Data Bridge
B1: Chart Data Bridge — Model → Deck Traceability
B3: The presentation's charts are generated from a data-extraction script that reads this workbook after recalculation — not retyped by hand. If assumptions change here, re-running the extraction script and the deck-build script refreshes every chart below to match. This sheet is the map between the two files.
B6: Deck Slide | C6: Chart / Figure | D6: Exact Source Cell(s) In This Workbook
B7: Slide 14 — Customer Acquisition Funnel | C7: Bar chart, 7 funnel steps | D7: 'Acquisition Funnel'!C4:C15 (one value per step)
B8: Slide 18 — 3-Year Financial Projection | C8: Disbursements & PBT, Years 1–3 | D8: '3-Year P&L'!C4:E4 (Disbursements), C18:E18 (PBT)
B9: Slide 20 — Scenario Analysis | C9: Worst / Base / Best PBT | D9: 'Scenario Analysis'!C10:E10
B10: Appendix (last slide) — Capital, IRR, NPV & Payback | C10: Headline & conservative IRR/NPV/payback | D10: 'Capital & Returns'!C8, C9, C10, C11, C12
B11: Slide 25 — Regulatory capital table | C11: Capital required, % CET1, ROIC by year | D11: 'Capital & Returns'!C18:E20
B12: Slide 26 — Implementation budget total | C12: ₹ cr total ask | D12: 'Implementation Budget'!C12
B13: Slide 28 — Executive KPI Dashboard | C13: 12-metric table, Year 3 column | D13: 'Executive KPI Dashboard'!C4:E15
B14: Slide 29 — Board Recommendation | C14: Investment ask, expected return, success metrics | D14: 'Implementation Budget'!C12; 'Capital & Returns'!C10, E20
